29-04-2025 01:05:34 - root - INFO - Запуск бота в Docker-контейнере
29-04-2025 01:05:34 - telegram.ext.Application - INFO - Application started
29-04-2025 01:08:46 - root - INFO - Получен файл: Справка_о_движении_денежных_средств.pdf
29-04-2025 01:08:46 - root - INFO - Начата обработка PDF: Справка_о_движении_денежных_средств.pdf, размер: 118274 байт
29-04-2025 01:08:46 - root - INFO - Используются настройки: return_files=0
29-04-2025 01:08:47 - camelot - INFO - Processing page-1
29-04-2025 01:08:48 - camelot - INFO - Processing page-2
29-04-2025 01:08:48 - camelot - INFO - Processing page-3
29-04-2025 01:08:48 - camelot - INFO - Processing page-4
29-04-2025 01:08:49 - camelot - INFO - Processing page-5
29-04-2025 01:08:49 - camelot - INFO - Processing page-6
29-04-2025 01:08:49 - camelot - INFO - Processing page-7
29-04-2025 01:08:49 - camelot - INFO - Processing page-8
29-04-2025 01:08:50 - extract_transactions_pdf2 - INFO - Обработка CSV как Tinkoff_Platinum
29-04-2025 01:08:50 - extract_transactions_pdf2 - INFO - Успешно загружен CSV для Tinkoff Platinum, строк: 414
29-04-2025 01:08:50 - extract_transactions_pdf2 - INFO - Данные сохранены в /tmp/transactions_processed_tinkoff_platinum.csv
29-04-2025 01:08:50 - root - ERROR - Исключение при обработке запроса:
Traceback (most recent call last):
  File "/root/.local/lib/python3.10/site-packages/telegram/ext/_application.py", line 1124, in process_update
    await coroutine
  File "/root/.local/lib/python3.10/site-packages/telegram/ext/_handler.py", line 141, in handle_update
    return await self.callback(update, context)
  File "/app/bot.py", line 92, in wrapper
    return await func(*args, **kwargs)
  File "/app/bot.py", line 1033, in handle_document
    await self.cleanup_files([
  File "/app/bot.py", line 84, in wrapper
    user_id = update.effective_user.id
AttributeError: 'list' object has no attribute 'effective_user'
